<?xml version="1.0" ?>
<robot name="finaldesign" xmlns:xacro="http://www.ros.org/wiki/xacro">

<xacro:include filename="$(find finaldesign_description)/urdf/materials.xacro" />
<xacro:include filename="$(find finaldesign_description)/urdf/finaldesign.trans" />
<xacro:include filename="$(find finaldesign_description)/urdf/finaldesign.gazebo" />
<link name="base_link">
  <inertial>
    <origin xyz="-0.0036570411146029298 9.64624872804682e-17 0.07733171782905483" rpy="0 0 0"/>
    <mass value="3.198140661088289"/>
    <inertia ixx="0.022396" iyy="0.025301" izz="0.046154" ixy="0.0" iyz="0.0" ixz="0.000252"/>
  </inertial>
  <visual>
    <origin xyz="0 0 0" rpy="0 0 0"/>
    <geometry>
      <mesh filename="package://finaldesign_description/meshes/base_link.stl" scale="0.001 0.001 0.001"/>
    </geometry>
    <material name="silver"/>
  </visual>
  <collision>
    <origin xyz="0 0 0" rpy="0 0 0"/>
    <geometry>
      <mesh filename="package://finaldesign_description/meshes/base_link.stl" scale="0.001 0.001 0.001"/>
    </geometry>
  </collision>
</link>

<link name="right_wheel_1">
  <inertial>
    <origin xyz="-1.2352049280260327e-17 0.015000000000000013 0.0" rpy="0 0 0"/>
    <mass value="0.3423845118560751"/>
    <inertia ixx="0.00036" iyy="0.000669" izz="0.00036" ixy="-0.0" iyz="0.0" ixz="-0.0"/>
  </inertial>
  <visual>
    <origin xyz="-0.0 -0.15 -0.0625" rpy="0 0 0"/>
    <geometry>
      <mesh filename="package://finaldesign_description/meshes/right_wheel_1.stl" scale="0.001 0.001 0.001"/>
    </geometry>
    <material name="silver"/>
  </visual>
  <collision>
    <origin xyz="-0.0 -0.15 -0.0625" rpy="0 0 0"/>
    <geometry>
      <mesh filename="package://finaldesign_description/meshes/right_wheel_1.stl" scale="0.001 0.001 0.001"/>
    </geometry>
  </collision>
</link>

<link name="left_wheel_1">
  <inertial>
    <origin xyz="-1.2352049280260327e-17 -0.015000000000000013 0.0" rpy="0 0 0"/>
    <mass value="0.3423845118560751"/>
    <inertia ixx="0.00036" iyy="0.000669" izz="0.00036" ixy="-0.0" iyz="0.0" ixz="-0.0"/>
  </inertial>
  <visual>
    <origin xyz="-0.0 0.15 -0.0625" rpy="0 0 0"/>
    <geometry>
      <mesh filename="package://finaldesign_description/meshes/left_wheel_1.stl" scale="0.001 0.001 0.001"/>
    </geometry>
    <material name="silver"/>
  </visual>
  <collision>
    <origin xyz="-0.0 0.15 -0.0625" rpy="0 0 0"/>
    <geometry>
      <mesh filename="package://finaldesign_description/meshes/left_wheel_1.stl" scale="0.001 0.001 0.001"/>
    </geometry>
  </collision>
</link>

<link name="Component8_1">
  <inertial>
    <origin xyz="0.0 0.0 0.009999999999999995" rpy="0 0 0"/>
    <mass value="0.1348685726186098"/>
    <inertia ixx="7.3e-05" iyy="7.3e-05" izz="0.000137" ixy="-0.0" iyz="-0.0" ixz="0.0"/>
  </inertial>
  <visual>
    <origin xyz="0.09 -0.0 -0.1075" rpy="0 0 0"/>
    <geometry>
      <mesh filename="package://finaldesign_description/meshes/Component8_1.stl" scale="0.001 0.001 0.001"/>
    </geometry>
    <material name="silver"/>
  </visual>
  <collision>
    <origin xyz="0.09 -0.0 -0.1075" rpy="0 0 0"/>
    <geometry>
      <mesh filename="package://finaldesign_description/meshes/Component8_1.stl" scale="0.001 0.001 0.001"/>
    </geometry>
  </collision>
</link>

<link name="Component2_1">
  <inertial>
    <origin xyz="0.09194772525892057 0.04 0.024637318729006485" rpy="0 0 0"/>
    <mass value="0.29750431282622997"/>
    <inertia ixx="0.000156" iyy="0.001374" izz="0.001308" ixy="-0.0" iyz="0.0" ixz="-0.000332"/>
  </inertial>
  <visual>
    <origin xyz="-0.0 0.04 -0.1525" rpy="0 0 0"/>
    <geometry>
      <mesh filename="package://finaldesign_description/meshes/Component2_1.stl" scale="0.001 0.001 0.001"/>
    </geometry>
    <material name="silver"/>
  </visual>
  <collision>
    <origin xyz="-0.0 0.04 -0.1525" rpy="0 0 0"/>
    <geometry>
      <mesh filename="package://finaldesign_description/meshes/Component2_1.stl" scale="0.001 0.001 0.001"/>
    </geometry>
  </collision>
</link>

<link name="Component3_1">
  <inertial>
    <origin xyz="0.11210365947142531 0.04935903979651904 0.03077041053487456" rpy="0 0 0"/>
    <mass value="0.3506940885621103"/>
    <inertia ixx="0.001106" iyy="0.000859" izz="0.001804" ixy="-2.5e-05" iyz="-7e-06" ixz="-0.000202"/>
  </inertial>
  <visual>
    <origin xyz="-0.193185 0.02 -0.204264" rpy="0 0 0"/>
    <geometry>
      <mesh filename="package://finaldesign_description/meshes/Component3_1.stl" scale="0.001 0.001 0.001"/>
    </geometry>
    <material name="silver"/>
  </visual>
  <collision>
    <origin xyz="-0.193185 0.02 -0.204264" rpy="0 0 0"/>
    <geometry>
      <mesh filename="package://finaldesign_description/meshes/Component3_1.stl" scale="0.001 0.001 0.001"/>
    </geometry>
  </collision>
</link>

<joint name="Revolute 1" type="continuous">
  <origin xyz="0.0 0.15 0.0625" rpy="0 0 0"/>
  <parent link="base_link"/>
  <child link="right_wheel_1"/>
  <axis xyz="0.0 1.0 0.0"/>
</joint>

<joint name="Revolute 2" type="continuous">
  <origin xyz="0.0 -0.15 0.0625" rpy="0 0 0"/>
  <parent link="base_link"/>
  <child link="left_wheel_1"/>
  <axis xyz="0.0 -1.0 0.0"/>
</joint>

<joint name="Rigid 3" type="fixed">
  <origin xyz="-0.09 0.0 0.1075" rpy="0 0 0"/>
  <parent link="base_link"/>
  <child link="Component8_1"/>
</joint>

<joint name="Revolute 4" type="revolute">
  <origin xyz="0.0 -0.04 0.1525" rpy="0 0 0"/>
  <parent link="base_link"/>
  <child link="Component2_1"/>
  <axis xyz="0.0 -1.0 0.0"/>
  <limit upper="2.96706" lower="0.261799" effort="100" velocity="100"/>
</joint>

<joint name="Revolute 7" type="continuous">
  <origin xyz="0.193185 0.02 0.051764" rpy="0 0 0"/>
  <parent link="Component2_1"/>
  <child link="Component3_1"/>
  <axis xyz="0.0 1.0 0.0"/>
</joint>

</robot>
